<?xml version="1.0" ?>
<!-- Generated using onshape-to-robot -->
<!-- Onshape https://cad.onshape.com/documents/804927696f06d877f3f1803e/w/a6ec5b04280208e722189e15/e/eee1ab796d84f4ff324d3a02 -->
<mujoco model="microduck">
  <compiler angle="radian" meshdir="assets" autolimits="true"/>
  <default>
    <default class="microduck">
      <joint frictionloss="0.1" armature="0.005"/>
      <position kp="50" dampratio="1"/>
      <default class="visual">
        <geom type="mesh" contype="0" conaffinity="0" group="2"/>
      </default>
      <default class="collision">
        <geom group="3"/>
      </default>
    </default>
  </default>
  <!-- Additional joints_properties.xml -->
  <default>
    <default class="perfect_actuator">
      <geom contype="0" conaffinity="0"/>
      <joint damping="0.15" frictionloss="0.1" armature="0.001"/>
      <position kp="10.0" kv="0.1" forcerange="-20.0 20.0"/>
    </default>
    <default class="chosen_actuator">
      <geom contype="0" conaffinity="0"/>
      <joint damping="0.048" frictionloss="0.006" armature="0.002"/>
      <position kp="0.52" kv="0.0" forcerange="-0.91 0.91" ctrlrange="-10.0 10.0"/>
    </default>
  </default>
  <!-- Additional sensors.xml -->
  <sensor>
    <framequat name="orientation" objtype="site" noise="0.001" objname="imu"/>
    <gyro name="angular-velocity" site="imu" noise="0.005"/>
    <gyro name="imu_ang_vel" site="imu"/>
    <velocimeter name="imu_lin_vel" site="imu"/>
    <accelerometer name="imu_accel" site="imu"/>
    <subtreeangmom name="root_angmom" body="trunk_base"/>
  </sensor>
  <!-- Additional additional.xml -->
  <default>
    <default class="self_collision_only">
      <geom group="3" contype="2" conaffinity="2"/>
    </default>
  </default>
  <worldbody>
    <!-- Link trunk_base -->
    <body name="trunk_base" pos="0 0 0.12" quat="1 0 0 0" childclass="microduck">
      <freejoint name="trunk_base_freejoint"/>
      <inertial pos="-0.0141125 -0.000111648 0.0198336" mass="0.385924" fullinertia="0.000464287 0.000556195 0.000395643 6.35835e-08 -2.47128e-05 4.24564e-07"/>
      <!-- Part cell -->
      <geom type="mesh" class="visual" pos="-0.0263454 0.00899934 -0.0228" quat="1 -1.11022e-16 -0 -4.44089e-16" mesh="cell" material="cell_material"/>
      <!-- Part xl330 -->
      <geom type="mesh" class="visual" pos="0.0125202 -0.02 0.0353" quat="4.06839e-22 -0.707107 0 -0.707107" mesh="xl330" material="xl330_material"/>
      <!-- Part bms -->
      <geom type="mesh" class="visual" pos="-0.0398454 0.0620566 -0.00623206" quat="0.707107 -1.17867e-16 -0.707107 3.13162e-17" mesh="bms" material="bms_material"/>
      <!-- Part uc_boards -->
      <geom type="mesh" class="visual" pos="0.0125202 -9.32051e-17 0.0351" quat="1 -5.20961e-17 -2.22045e-16 -1.66618e-17" mesh="uc_boards" material="uc_boards_material"/>
      <!-- Part bottom_shell -->
      <geom type="mesh" class="visual" pos="0.0125202 1.69448e-16 0.0352" quat="1 -0 -2.22045e-16 -0" mesh="bottom_shell" material="bottom_shell_material"/>
      <geom type="mesh" class="collision" pos="0.0125202 1.69448e-16 0.0352" quat="1 -0 -2.22045e-16 -0" mesh="bottom_shell" material="bottom_shell_material"/>
      <!-- Part usb_c_charger -->
      <geom type="mesh" class="visual" pos="-0.0261798 0.01855 -0.01105" quat="0.5 -0.5 0.5 0.5" mesh="usb_c_charger" material="usb_c_charger_material"/>
      <!-- Part bearing -->
      <geom type="mesh" class="visual" pos="0.0125202 -0.04 0.0352" quat="1 0 1.2446e-60 2.07321e-39" mesh="bearing" material="bearing_material"/>
      <!-- Part trunk_yaw -->
      <geom type="mesh" class="visual" pos="0.0125202 7.42261e-19 0.0352" quat="1 0 1.10728e-16 8.07177e-18" mesh="trunk_yaw" material="trunk_yaw_material"/>
      <!-- Part jumper -->
      <geom type="mesh" class="visual" pos="0.0149458 -0.232101 0.0567" quat="0.707107 1.11022e-16 -2.22045e-16 -0.707107" mesh="jumper" material="jumper_material"/>
      <!-- Part holder -->
      <geom type="mesh" class="visual" pos="-0.0388454 -0.0645251 0.00914152" quat="0.707107 -1.19672e-16 0.707107 -1.23285e-16" mesh="holder" material="holder_material"/>
      <!-- Part bno055 -->
      <geom type="mesh" class="visual" pos="-0.0284798 0.0225 0.0581" quat="2.41484e-18 -0.707107 -0.707107 7.60898e-17" mesh="bno055" material="bno055_material"/>
      <!-- Part xl330_2 -->
      <geom type="mesh" class="visual" pos="0.0125202 0.02 0.0353" quat="1.58977e-15 0.707107 -1.66533e-15 0.707107" mesh="xl330" material="xl330_material"/>
      <!-- Part top_shell -->
      <geom type="mesh" class="visual" pos="0.0124202 1.72207e-16 0.0352" quat="1 -1.11022e-16 -1.11022e-16 2.64698e-23" mesh="top_shell" material="top_shell_material"/>
      <geom type="mesh" class="collision" pos="0.0124202 1.72207e-16 0.0352" quat="1 -1.11022e-16 -1.11022e-16 2.64698e-23" mesh="top_shell" material="top_shell_material"/>
      <!-- Part xl330_3 -->
      <geom type="mesh" class="visual" pos="0.0375202 0.0001 0.0552" quat="0.707107 1.77773e-16 -0 0.707107" mesh="xl330" material="xl330_material"/>
      <!-- Part uc_inside_holder -->
      <geom type="mesh" class="visual" pos="0.00935462 0.000949336 0.035" quat="1 2.31691e-16 -2.22045e-16 -5.85917e-16" mesh="uc_inside_holder" material="uc_inside_holder_material"/>
      <!-- Part raspberrypizerow -->
      <geom type="mesh" class="visual" pos="0.00299522 -2.5e-05 0.0533" quat="0.5 0.5 -0.5 -0.5" mesh="raspberrypizerow" material="raspberrypizerow_material"/>
      <!-- Part bearing_2 -->
      <geom type="mesh" class="visual" pos="0.0125202 -1.56125e-17 0.0352" quat="1 0 0 0" mesh="bearing" material="bearing_material"/>
      <!-- Part jack -->
      <geom type="mesh" class="visual" pos="-0.00792308 -0.182013 0.0567" quat="0.707107 -1.07858e-16 1.11022e-16 -0.707107" mesh="jack" material="jack_material"/>
      <!-- Part board -->
      <geom type="mesh" class="visual" pos="-0.0479798 0.00949999 0.0567" quat="0.707107 -1.66533e-16 -2.22045e-16 -0.707107" mesh="board" material="board_material"/>
      <!-- Part trunk_base -->
      <geom type="mesh" class="visual" pos="0.0125202 9.59102e-19 0.0352" quat="1 0 -7.13694e-17 2.17467e-16" mesh="trunk_base" material="trunk_base_material"/>
      <geom type="mesh" class="collision" pos="0.0125202 9.59102e-19 0.0352" quat="1 0 -7.13694e-17 2.17467e-16" mesh="trunk_base" material="trunk_base_material"/>
      <!-- Part power_switch -->
      <geom type="mesh" class="visual" pos="-0.0423998 0.0318 0.017165" quat="0.707107 -0 -0.707107 -0" mesh="power_switch" material="power_switch_material"/>
      <!-- Part cell_2 -->
      <geom type="mesh" class="visual" pos="-0.0263454 -0.0110007 -0.0228" quat="1 -1.69241e-16 1.11022e-16 -4.50549e-16" mesh="cell" material="cell_material"/>
      <!-- Part power_switch_2 -->
      <geom type="mesh" class="visual" pos="-0.0423998 -0.0318 0.017165" quat="0.707107 0 -0.707107 1.02884e-24" mesh="power_switch" material="power_switch_material"/>
      <!-- Part uc -->
      <geom type="mesh" class="visual" pos="0.0125202 -4.59177e-41 0.0351" quat="1 0 1.1583e-16 5.76021e-18" mesh="uc" material="uc_material"/>
      <!-- Frame imu -->
      <site group="3" name="imu" pos="-0.0284798 0.0227226 0.0581" quat="1 1.01491e-17 1.11022e-16 -3.32489e-16"/>
      <!-- Link roll_motor_bottom -->
      <body name="roll_motor_bottom" pos="0.0125202 0.02 0.0208" quat="2.30212e-15 -0.707107 0.707107 -2.30212e-15">
        <!-- Joint from trunk_base to roll_motor_bottom -->
        <joint axis="0 0 1" name="left_hip_yaw" type="hinge" range="-0.5235987755982988 0.5235987755982988" class="chosen_actuator"/>
        <inertial pos="5.35289e-17 -0.000237525 0.0207938" mass="0.0252944" fullinertia="5.67885e-06 5.1295e-06 2.4759e-06 2.52995e-20 -5.61967e-21 -2.1555e-08"/>
        <!-- Part roll_motor_bottom -->
        <geom type="mesh" class="visual" pos="0.02 -5e-05 -0.0146" quat="2.31445e-15 0.707107 -0.707107 2.23304e-15" mesh="roll_motor_bottom" material="roll_motor_bottom_material"/>
        <!-- Part roll_motor_top -->
        <geom type="mesh" class="visual" pos="0.02 1.56125e-17 -0.0146" quat="2.35117e-15 0.707107 -0.707107 2.32713e-15" mesh="roll_motor_top" material="roll_motor_top_material"/>
        <!-- Part xl330_4 -->
        <geom type="mesh" class="visual" pos="6.245e-17 -5e-05 0.0286" quat="0.707107 -2.24671e-15 2.47025e-15 0.707107" mesh="xl330" material="xl330_material"/>
        <!-- Link left_roll_to_pitch -->
        <body name="left_roll_to_pitch" pos="-6.93889e-17 -0.01455 0.0286" quat="1.54368e-15 -1.60333e-15 -0.707107 0.707107">
          <!-- Joint from roll_motor_bottom to left_roll_to_pitch -->
          <joint axis="0 0 1" name="left_hip_roll" type="hinge" range="-0.6981317007977318 0.6981317007977318" class="chosen_actuator"/>
          <inertial pos="0.034947 0.00019824 -0.0134625" mass="0.0304845" fullinertia="5.39431e-06 9.58888e-06 6.71172e-06 9.64608e-08 -4.86513e-08 2.08504e-08"/>
          <!-- Part left_roll_to_pitch -->
          <geom type="mesh" class="visual" pos="-0.02 0.0432 -0.0145" quat="0.5 -0.5 -0.5 -0.5" mesh="left_roll_to_pitch" material="left_roll_to_pitch_material"/>
          <!-- Part xl330_5 -->
          <geom type="mesh" class="visual" pos="0.0399 7.11237e-17 -0.0245" quat="1.70304e-16 4.29167e-16 1 -5.06908e-16" mesh="xl330" material="xl330_material"/>
          <!-- Link leg_plate -->
          <body name="leg_plate" pos="0.0544 7.97973e-17 -0.0245" quat="0.5 0.5 0.5 0.5">
            <!-- Joint from left_roll_to_pitch to leg_plate -->
            <joint axis="0 0 1" name="left_hip_pitch" type="hinge" range="-8.881784197001252e-16 1.5707963267948957" class="chosen_actuator"/>
            <inertial pos="-0.0297714 4.83594e-18 -0.0142481" mass="0.0243882" fullinertia="3.34584e-06 6.61117e-06 5.2143e-06 -1.15359e-21 1.98369e-08 -3.42328e-14"/>
            <!-- Part leg_plate -->
            <geom type="mesh" class="visual" pos="0.0432 -0.01 0.0455" quat="0.5 -0.5 0.5 -0.5" mesh="leg_plate" material="leg_plate_material"/>
            <geom type="mesh" class="collision" pos="0.0432 -0.01 0.0455" quat="0.5 -0.5 0.5 -0.5" mesh="leg_plate" material="leg_plate_material"/>
            <!-- Part leg_plate_2 -->
            <geom type="mesh" class="visual" pos="0.0432 0.01 -0.0745" quat="0.5 0.5 0.5 0.5" mesh="leg_plate" material="leg_plate_material"/>
            <geom type="mesh" class="collision" pos="0.0432 0.01 -0.0745" quat="0.5 0.5 0.5 0.5" mesh="leg_plate" material="leg_plate_material"/>
            <!-- Part xl330_6 -->
            <geom type="mesh" class="visual" pos="-0.042 -2.60209e-17 -0.0145" quat="9.65923e-16 -0.707107 -1.55431e-15 0.707107" mesh="xl330" material="xl330_material"/>
            <!-- Link leg_plate_2 -->
            <body name="leg_plate_2" pos="-0.042 -7.93636e-17 0" quat="0.707107 9.3236e-16 1.44329e-15 -0.707107">
              <!-- Joint from leg_plate to leg_plate_2 -->
              <joint axis="0 0 1" name="left_knee" type="hinge" range="-1.9198621771937625 -0.0" class="chosen_actuator"/>
              <inertial pos="2.76392e-17 -0.0297714 -0.0142481" mass="0.0243882" fullinertia="6.61117e-06 3.34584e-06 5.2143e-06 -6.57078e-22 3.42328e-14 1.98369e-08"/>
              <!-- Part leg_plate_3 -->
              <geom type="mesh" class="visual" pos="-0.01 0.0432 -0.0745" quat="1.39106e-15 9.44385e-16 -0.707107 -0.707107" mesh="leg_plate" material="leg_plate_material"/>
              <geom type="mesh" class="collision" pos="-0.01 0.0432 -0.0745" quat="1.39106e-15 9.44385e-16 -0.707107 -0.707107" mesh="leg_plate" material="leg_plate_material"/>
              <!-- Part leg_plate_4 -->
              <geom type="mesh" class="visual" pos="0.01 0.0432 0.0455" quat="0.707107 -0.707107 -1.22125e-15 6.15588e-16" mesh="leg_plate" material="leg_plate_material"/>
              <geom type="mesh" class="collision" pos="0.01 0.0432 0.0455" quat="0.707107 -0.707107 -1.22125e-15 6.15588e-16" mesh="leg_plate" material="leg_plate_material"/>
              <!-- Part xl330_7 -->
              <geom type="mesh" class="visual" pos="3.16587e-17 -0.042 -0.0145" quat="0.5 0.5 0.5 -0.5" mesh="xl330" material="xl330_material"/>
              <!-- Link foot_tpu_bottom -->
              <body name="foot_tpu_bottom" pos="3.16587e-17 -0.042 1.38778e-17" quat="1.38778e-17 7.01222e-17 1.11022e-16 1">
                <!-- Joint from leg_plate_2 to foot_tpu_bottom -->
                <joint axis="0 0 1" name="left_ankle" type="hinge" range="-1.5707963267948966 1.5707963267948966" class="chosen_actuator"/>
                <inertial pos="0.00475212 0.0143399 -0.0145" mass="0.0190505" fullinertia="3.25184e-06 6.82459e-06 4.90623e-06 -9.55165e-08 -2.23326e-11 -8.15886e-12"/>
                <!-- Part foot -->
                <geom type="mesh" class="visual" pos="0.01 -0.1272 -0.0745" quat="0.707107 0.707107 -0 7.91486e-33" mesh="foot" material="foot_material"/>
                <geom type="mesh" class="collision" pos="0.01 -0.1272 -0.0745" quat="0.707107 0.707107 -0 7.91486e-33" mesh="foot" material="foot_material"/>
                <!-- Part foot_tpu_bottom -->
                <geom type="mesh" class="visual" pos="0.01 -0.1272 -0.0745" quat="0.707107 0.707107 0 1.18106e-23" mesh="foot_tpu_bottom" material="foot_tpu_bottom_material"/>
                <geom type="mesh" name="left_foot_collision" class="collision" pos="0.01 -0.1272 -0.0745" quat="0.707107 0.707107 0 1.18106e-23" mesh="foot_tpu_bottom" material="foot_tpu_bottom_material"/>
                <!-- Frame left_foot -->
                <site group="3" name="left_foot" pos="0.0048 0.021 -0.0145" quat="0.707107 0.707107 0 1.18106e-23"/>
              </body>
            </body>
          </body>
        </body>
      </body>
      <!-- Link long_neck_plate2 -->
      <body name="long_neck_plate2" pos="0.0375202 0.0146 0.0552" quat="1.1238e-17 1.87446e-16 -0.707107 -0.707107">
        <!-- Joint from trunk_base to long_neck_plate2 -->
        <joint axis="0 0 1" name="neck_pitch" type="hinge" range="-1.2217304763960306 2.0943951023931953" class="chosen_actuator"/>
        <inertial pos="-0.000906124 0.0428312 -0.0147016" mass="0.0304826" fullinertia="1.19433e-05 4.60094e-06 9.75412e-06 -5.05283e-07 5.56736e-09 5.01905e-08"/>
        <!-- Part long_neck_plate1 -->
        <geom type="mesh" class="visual" pos="0.025 -0.02 -0.0145" quat="2.65558e-16 -7.50183e-17 -0.707107 -0.707107" mesh="long_neck_plate1" material="long_neck_plate1_material"/>
        <!-- Part neck_reinforcement -->
        <geom type="mesh" class="visual" pos="0.025 -0.02 -0.0145" quat="9.50704e-17 -2.77431e-16 0.707107 0.707107" mesh="neck_reinforcement" material="neck_reinforcement_material"/>
        <!-- Part long_neck_plate2 -->
        <geom type="mesh" class="visual" pos="0.025 -0.02 -0.0145" quat="1.07581e-16 4.81496e-17 0.707107 0.707107" mesh="long_neck_plate2" material="long_neck_plate2_material"/>
        <!-- Part xl330_8 -->
        <geom type="mesh" class="visual" pos="-6.93889e-18 0.06 -0.0145" quat="0.5 -0.5 -0.5 -0.5" mesh="xl330" material="xl330_material"/>
        <!-- Link head_pitch_to_yaw -->
        <body name="head_pitch_to_yaw" pos="0 0.06 3.81639e-17" quat="1 2.10472e-16 -0 2.75973e-17">
          <!-- Joint from long_neck_plate2 to head_pitch_to_yaw -->
          <joint axis="0 0 1" name="head_pitch" type="hinge" range="-1.2217304763960306 1.2217304763960306" class="chosen_actuator"/>
          <inertial pos="0.00612022 0.0212216 -0.0145" mass="0.00847041" fullinertia="3.01296e-06 1.50757e-06 2.61412e-06 -4.42309e-07 -1.0103e-12 2.76775e-13"/>
          <!-- Part head_pitch_to_yaw -->
          <geom type="mesh" class="visual" pos="0.025 -0.08 -0.0145" quat="9.72317e-17 -9.7232e-17 0.707107 0.707107" mesh="head_pitch_to_yaw" material="head_pitch_to_yaw_material"/>
          <!-- Link head_yaw_to_roll -->
          <body name="head_yaw_to_roll" pos="1.38778e-17 0.0465 -0.0145" quat="9.7232e-17 3.33067e-16 0.707107 -0.707107">
            <!-- Joint from head_pitch_to_yaw to head_yaw_to_roll -->
            <joint axis="0 0 1" name="head_yaw" type="hinge" range="-2.6179938779914944 2.6179938779914944" class="chosen_actuator"/>
            <inertial pos="0.00569587 -1.1755e-17 0.0184874" mass="0.0379676" fullinertia="7.59409e-06 1.62671e-05 1.68278e-05 -4.46756e-22 1.16448e-06 1.35781e-21"/>
            <!-- Part head_yaw_to_roll -->
            <geom type="mesh" class="visual" pos="-0.025 -1.8838e-17 0.1265" quat="0 1 0 0" mesh="head_yaw_to_roll" material="head_yaw_to_roll_material"/>
            <!-- Part xl330_9 -->
            <geom type="mesh" class="visual" pos="6.93889e-18 2.43945e-19 0.0145" quat="2.00811e-29 0.707107 0 -0.707107" mesh="xl330" material="xl330_material"/>
            <!-- Link head_base_plate -->
            <body name="head_base_plate" pos="0.0305 -1.8838e-17 0.0145" quat="0.5 -0.5 0.5 -0.5">
              <!-- Joint from head_yaw_to_roll to head_base_plate -->
              <joint axis="0 0 1" name="head_roll" type="hinge" range="-0.5235987755983006 0.523598775598297" class="chosen_actuator"/>
              <inertial pos="0.00146865 -0.0018947 -0.0283349" mass="0.127405" fullinertia="0.000281176 0.000306847 6.95095e-05 -8.69966e-08 -8.01758e-06 -1.26406e-06"/>
              <!-- Part xl330_10 -->
              <geom type="mesh" class="visual" pos="-5e-05 0.009 -0.0791" quat="3.839e-16 -6.26385e-17 0.707107 0.707107" mesh="xl330" material="xl330_material"/>
              <!-- Part camera_spacer -->
              <geom type="mesh" class="visual" pos="3.66189e-17 -0.112 -0.0556" quat="0.5 -0.5 -0.5 -0.5" mesh="camera_spacer" material="camera_spacer_material"/>
              <!-- Part xl330_11 -->
              <geom type="mesh" class="visual" pos="-1.76183e-18 0 0.0145" quat="1.18042e-30 -0.707107 -0 0.707107" mesh="xl330" material="xl330_material"/>
              <!-- Part bearing_3 -->
              <geom type="mesh" class="visual" pos="-0.02 -1.94289e-16 -0.1215" quat="8.17756e-17 0.707107 0.707107 -8.17756e-17" mesh="bearing" material="bearing_material"/>
              <!-- Part head_top -->
              <geom type="mesh" class="visual" pos="3.24719e-17 -0.112 -0.0556" quat="0.5 -0.5 -0.5 -0.5" mesh="head_top" material="head_top_material"/>
              <geom type="mesh" class="collision" pos="3.24719e-17 -0.112 -0.0556" quat="0.5 -0.5 -0.5 -0.5" mesh="head_top" material="head_top_material"/>
              <!-- Part head_base_plate -->
              <geom type="mesh" class="visual" pos="2.08167e-17 -0.112 -0.0556" quat="0.5 -0.5 -0.5 -0.5" mesh="head_base_plate" material="head_base_plate_material"/>
              <!-- Frame mouth_tip -->
              <site group="3" name="mouth_tip" pos="2.78775e-17 -0.0175 0.0364" quat="0.5 -0.5 -0.5 -0.5"/>
            </body>
          </body>
        </body>
      </body>
      <!-- Link xl330 -->
      <body name="xl330" pos="0.0125202 -0.02 0.0208" quat="4.06756e-31 -1 -2.27596e-15 -2.47112e-17">
        <!-- Joint from trunk_base to xl330 -->
        <joint axis="0 0 1" name="right_hip_yaw" type="hinge" range="-0.5235987755983033 0.5235987755982944" class="chosen_actuator"/>
        <inertial pos="0.000237525 1.15876e-17 0.0207938" mass="0.0252944" fullinertia="5.1295e-06 5.67885e-06 2.4759e-06 -1.50086e-23 2.1555e-08 -6.01231e-21"/>
        <!-- Part roll_motor_top_2 -->
        <geom type="mesh" class="visual" pos="-1.73472e-18 0.02 -0.0146" quat="8.03113e-17 1 -0 0" mesh="roll_motor_top" material="roll_motor_top_material"/>
        <!-- Part roll_motor_bottom_2 -->
        <geom type="mesh" class="visual" pos="5e-05 0.02 -0.0146" quat="8.03113e-17 1 0 -9.03502e-17" mesh="roll_motor_bottom" material="roll_motor_bottom_material"/>
        <!-- Part xl330_12 -->
        <geom type="mesh" class="visual" pos="5e-05 2.08167e-17 0.0286" quat="3.86542e-33 -1.66533e-16 -0 -1" mesh="xl330" material="xl330_material"/>
        <!-- Link right_roll_to_pitch -->
        <body name="right_roll_to_pitch" pos="0.01455 2.42861e-17 0.0286" quat="0.5 -0.5 0.5 -0.5">
          <!-- Joint from xl330 to right_roll_to_pitch -->
          <joint axis="0 0 1" name="right_hip_roll" type="hinge" range="-0.6981317007977318 0.6981317007977318" class="chosen_actuator"/>
          <inertial pos="-0.034947 0.00019824 -0.0134625" mass="0.0304845" fullinertia="5.39431e-06 9.58888e-06 6.71172e-06 -9.64608e-08 4.86513e-08 2.08504e-08"/>
          <!-- Part right_roll_to_pitch -->
          <geom type="mesh" class="visual" pos="0.02 0.0432 -0.0145" quat="0.5 -0.5 -0.5 -0.5" mesh="right_roll_to_pitch" material="right_roll_to_pitch_material"/>
          <!-- Part xl330_13 -->
          <geom type="mesh" class="visual" pos="-0.0399 -1.19522e-15 -0.0245" quat="4.8694e-15 1 -4.88498e-15 3.17801e-15" mesh="xl330" material="xl330_material"/>
          <!-- Link xl330_2 -->
          <body name="xl330_2" pos="-0.0544 -1.19522e-15 -0.0245" quat="0.5 0.5 -0.5 -0.5">
            <!-- Joint from right_roll_to_pitch to xl330_2 -->
            <joint axis="0 0 1" name="right_hip_pitch" type="hinge" range="-1.570796326794877 1.9539925233402755e-14" class="chosen_actuator"/>
            <inertial pos="0.0297714 1.14947e-16 -0.0142481" mass="0.0243882" fullinertia="3.34584e-06 6.61117e-06 5.2143e-06 5.98606e-20 -1.98369e-08 3.42327e-14"/>
            <!-- Part xl330_14 -->
            <geom type="mesh" class="visual" pos="0.042 1.20997e-16 -0.0145" quat="0.707107 1.74719e-15 0.707107 -5.81115e-15" mesh="xl330" material="xl330_material"/>
            <!-- Part leg_plate_5 -->
            <geom type="mesh" class="visual" pos="-0.0432 0.01 0.0455" quat="0.5 -0.5 -0.5 0.5" mesh="leg_plate" material="leg_plate_material"/>
            <geom type="mesh" class="collision" pos="-0.0432 0.01 0.0455" quat="0.5 -0.5 -0.5 0.5" mesh="leg_plate" material="leg_plate_material"/>
            <!-- Part leg_plate_6 -->
            <geom type="mesh" class="visual" pos="-0.0432 -0.01 -0.0745" quat="0.5 0.5 -0.5 -0.5" mesh="leg_plate" material="leg_plate_material"/>
            <geom type="mesh" class="collision" pos="-0.0432 -0.01 -0.0745" quat="0.5 0.5 -0.5 -0.5" mesh="leg_plate" material="leg_plate_material"/>
            <!-- Link xl330_3 -->
            <body name="xl330_3" pos="0.042 1.06252e-16 -8.88178e-16" quat="0.707107 1.44761e-15 5.44009e-15 0.707107">
              <!-- Joint from xl330_2 to xl330_3 -->
              <joint axis="0 0 1" name="right_knee" type="hinge" range="-1.7763568394002505e-15 1.9198621771937607" class="chosen_actuator"/>
              <inertial pos="-1.82572e-17 -0.0297714 -0.0142481" mass="0.0243882" fullinertia="6.61117e-06 3.34584e-06 5.2143e-06 -3.92164e-23 3.42328e-14 1.98369e-08"/>
              <!-- Part xl330_15 -->
              <geom type="mesh" class="visual" pos="-2.42861e-17 -0.042 -0.0145" quat="0.5 0.5 0.5 -0.5" mesh="xl330" material="xl330_material"/>
              <!-- Part leg_plate_7 -->
              <geom type="mesh" class="visual" pos="0.01 0.0432 0.0455" quat="0.707107 -0.707107 -6.66134e-16 -3.95672e-16" mesh="leg_plate" material="leg_plate_material"/>
              <geom type="mesh" class="collision" pos="0.01 0.0432 0.0455" quat="0.707107 -0.707107 -6.66134e-16 -3.95672e-16" mesh="leg_plate" material="leg_plate_material"/>
              <!-- Part leg_plate_8 -->
              <geom type="mesh" class="visual" pos="-0.01 0.0432 -0.0745" quat="2.4029e-17 -3.67484e-16 0.707107 0.707107" mesh="leg_plate" material="leg_plate_material"/>
              <geom type="mesh" class="collision" pos="-0.01 0.0432 -0.0745" quat="2.4029e-17 -3.67484e-16 0.707107 0.707107" mesh="leg_plate" material="leg_plate_material"/>
              <!-- Link foot -->
              <body name="foot" pos="-1.95156e-17 -0.042 1.38778e-17" quat="1 1.30061e-16 -0 3.93346e-16">
                <!-- Joint from xl330_3 to foot -->
                <joint axis="0 0 1" name="right_ankle" type="hinge" range="-1.5707963267948983 1.5707963267948948" class="chosen_actuator"/>
                <inertial pos="0.00475212 -0.0143399 -0.0145" mass="0.0190505" fullinertia="3.25184e-06 6.82459e-06 4.90623e-06 9.55165e-08 2.23326e-11 -8.15886e-12"/>
                <!-- Part foot_2 -->
                <geom type="mesh" class="visual" pos="0.01 0.1272 0.0455" quat="0.707107 -0.707107 0 2.3296e-33" mesh="foot" material="foot_material"/>
                <geom type="mesh" class="collision" pos="0.01 0.1272 0.0455" quat="0.707107 -0.707107 0 2.3296e-33" mesh="foot" material="foot_material"/>
                <!-- Part foot_tpu_bottom_2 -->
                <geom type="mesh" class="visual" pos="0.01 0.1272 0.0455" quat="0.707107 -0.707107 -0 2.87493e-20" mesh="foot_tpu_bottom" material="foot_tpu_bottom_material"/>
                <geom type="mesh" name="right_foot_collision" class="collision" pos="0.01 0.1272 0.0455" quat="0.707107 -0.707107 -0 2.87493e-20" mesh="foot_tpu_bottom" material="foot_tpu_bottom_material"/>
                <!-- Frame right_foot -->
                <site group="3" name="right_foot" pos="0.0048 -0.021 -0.0145" quat="0.707107 -0.707107 -0 2.87493e-20"/>
              </body>
            </body>
          </body>
        </body>
      </body>
    </body>
  </worldbody>
  <asset>
    <mesh file="xl330.stl"/>
    <mesh file="raspberrypizerow.stl"/>
    <mesh file="long_neck_plate2.stl"/>
    <mesh file="trunk_base.stl"/>
    <mesh file="leg_plate.stl"/>
    <mesh file="foot.stl"/>
    <mesh file="left_roll_to_pitch.stl"/>
    <mesh file="head_yaw_to_roll.stl"/>
    <mesh file="uc_boards.stl"/>
    <mesh file="jumper.stl"/>
    <mesh file="roll_motor_top.stl"/>
    <mesh file="neck_reinforcement.stl"/>
    <mesh file="board.stl"/>
    <mesh file="right_roll_to_pitch.stl"/>
    <mesh file="bearing.stl"/>
    <mesh file="bno055.stl"/>
    <mesh file="uc.stl"/>
    <mesh file="jack.stl"/>
    <mesh file="power_switch.stl"/>
    <mesh file="bms.stl"/>
    <mesh file="head_pitch_to_yaw.stl"/>
    <mesh file="cell.stl"/>
    <mesh file="foot_tpu_bottom.stl"/>
    <mesh file="trunk_yaw.stl"/>
    <mesh file="usb_c_charger.stl"/>
    <mesh file="bottom_shell.stl"/>
    <mesh file="top_shell.stl"/>
    <mesh file="uc_inside_holder.stl"/>
    <mesh file="long_neck_plate1.stl"/>
    <mesh file="head_base_plate.stl"/>
    <mesh file="roll_motor_bottom.stl"/>
    <mesh file="head_top.stl"/>
    <mesh file="holder.stl"/>
    <mesh file="camera_spacer.stl"/>
    <material name="cell_material" rgba="0.615686 0.811765 0.929412 1"/>
    <material name="xl330_material" rgba="0.286275 0.286275 0.286275 1"/>
    <material name="bms_material" rgba="0.231373 0.380392 0.705882 1"/>
    <material name="uc_boards_material" rgba="0.972549 0.529412 0.00392157 1"/>
    <material name="bottom_shell_material" rgba="0.6 0.6 0.6 1"/>
    <material name="usb_c_charger_material" rgba="0.615686 0.811765 0.929412 1"/>
    <material name="bearing_material" rgba="0.701961 0.701961 0.701961 1"/>
    <material name="trunk_yaw_material" rgba="0.235294 0.235294 0.235294 1"/>
    <material name="jumper_material" rgba="0.498039 0.498039 0.498039 1"/>
    <material name="holder_material" rgba="0.647059 0.647059 0.647059 1"/>
    <material name="bno055_material" rgba="0.615686 0.811765 0.929412 1"/>
    <material name="top_shell_material" rgba="0.6 0.6 0.6 1"/>
    <material name="uc_inside_holder_material" rgba="0.615686 0.811765 0.929412 1"/>
    <material name="raspberrypizerow_material" rgba="0.231373 0.380392 0.705882 1"/>
    <material name="jack_material" rgba="0.647059 0.647059 0.647059 1"/>
    <material name="board_material" rgba="0 0.501961 0 1"/>
    <material name="trunk_base_material" rgba="0.235294 0.235294 0.235294 1"/>
    <material name="power_switch_material" rgba="0.901961 0.901961 0.901961 1"/>
    <material name="uc_material" rgba="0.768627 0.886275 0.952941 1"/>
    <material name="roll_motor_bottom_material" rgba="0.235294 0.235294 0.235294 1"/>
    <material name="roll_motor_top_material" rgba="0.235294 0.235294 0.235294 1"/>
    <material name="left_roll_to_pitch_material" rgba="0.235294 0.235294 0.235294 1"/>
    <material name="leg_plate_material" rgba="0.235294 0.235294 0.235294 1"/>
    <material name="foot_material" rgba="1 0.756863 0.054902 1"/>
    <material name="foot_tpu_bottom_material" rgba="0.262745 0.262745 0.262745 1"/>
    <material name="long_neck_plate1_material" rgba="0.235294 0.235294 0.235294 1"/>
    <material name="neck_reinforcement_material" rgba="0.235294 0.235294 0.235294 1"/>
    <material name="long_neck_plate2_material" rgba="0.235294 0.235294 0.235294 1"/>
    <material name="head_pitch_to_yaw_material" rgba="0.235294 0.235294 0.235294 1"/>
    <material name="head_yaw_to_roll_material" rgba="0.235294 0.235294 0.235294 1"/>
    <material name="camera_spacer_material" rgba="0.917647 0.917647 0.917647 1"/>
    <material name="head_top_material" rgba="0.6 0.6 0.6 1"/>
    <material name="head_base_plate_material" rgba="0.235294 0.235294 0.235294 1"/>
    <material name="right_roll_to_pitch_material" rgba="0.235294 0.235294 0.235294 1"/>
  </asset>
  <actuator>
    <position class="chosen_actuator" name="left_hip_yaw" joint="left_hip_yaw"/>
    <position class="chosen_actuator" name="left_hip_roll" joint="left_hip_roll"/>
    <position class="chosen_actuator" name="left_hip_pitch" joint="left_hip_pitch"/>
    <position class="chosen_actuator" name="left_knee" joint="left_knee"/>
    <position class="chosen_actuator" name="left_ankle" joint="left_ankle"/>
    <position class="chosen_actuator" name="neck_pitch" joint="neck_pitch"/>
    <position class="chosen_actuator" name="head_pitch" joint="head_pitch"/>
    <position class="chosen_actuator" name="head_yaw" joint="head_yaw"/>
    <position class="chosen_actuator" name="head_roll" joint="head_roll"/>
    <position class="chosen_actuator" name="right_hip_yaw" joint="right_hip_yaw"/>
    <position class="chosen_actuator" name="right_hip_roll" joint="right_hip_roll"/>
    <position class="chosen_actuator" name="right_hip_pitch" joint="right_hip_pitch"/>
    <position class="chosen_actuator" name="right_knee" joint="right_knee"/>
    <position class="chosen_actuator" name="right_ankle" joint="right_ankle"/>
  </actuator>
  <equality/>
</mujoco>
